Workbook
Name July_accrual: #REF!
Name LINE8_PH: 'Line 3'!$AE$5:$AG$8
Name Names: #REF!
Name Public_Holiday: '[1]Line 11'!$X$5:$X$8
Name Public_Holiday: #REF!
Name T: #REF!

Sheet Sheet1
D2: Apr
D3: 44289 | E3: 44290 | F3: 44291 | G3: 44292 | H3: 44293 | I3: 44294 | J3: 44295 | M3: 44296 | N3: 44297 | O3: 44298 | P3: 44299 | Q3: 44300 | R3: 44301 | S3: 44302 | V3: 44303 | W3: 44304 | X3: 44305 | Y3: 44306 | Z3: 44307 | AA3: 44308 | AB3: 44309 | AE3: 44310 | AF3: 44311 | AG3: 44312 | AH3: 44313 | AI3: 44314 | AJ3: 44315 | AK3: 44316
A4: Employee Name | B4: Work Center | C4: ID | D4: Sa | E4: Su | F4: M | G4: Tu | H4: W | I4: Th | J4: F | K4: OT | L4: PH | M4: Sa | N4: Su | O4: M | P4: Tu | Q4: W | R4: Th | S4: F | T4: OT | U4: PH | V4: Sa | W4: Su | X4: M | Y4: Tu | Z4: W | AA4: Th | AB4: F | AC4: OT | AD4: PH | AE4: Sa | AF4: Su | AG4: M | AH4: Tu | AI4: W | AJ4: Th | AK4: F | AL4: OT | AM4: PH
A5: ADEBAYO, EMMANUEL ADEWALE | B5: 3 | C5: 18004071 | D5: 14 | E5: 10 | F5: 0 | G5: 14 | H5: 10 | I5: 0 | J5: 14 | K5: 30 | L5: 0 | M5: 10 | N5: 0 | O5: 14 | P5: 10 | Q5: 0 | R5: 0 | S5: 7 | T5: 1 | U5: 0 | V5: 7 | W5: 7 | X5: 7 | Y5: 10 | Z5: 10 | AA5: 0 | AB5: 0 | AC5: 1 | AD5: 0 | AE5: 7 | AF5: 7 | AG5: 7 | AH5: 7 | AI5: 10 | AJ5: 10 | AK5: 0 | AL5: 8 | AM5: 0
A6: IHUOMA, CHIMA MAXIMILLIAN | B6: 3 | C6: 18004357 | D6: 0 | E6: 14 | F6: 10 | G6: 0 | H6: 14 | I6: 10 | J6: 0 | K6: 6 | L6: 10 | M6: 14 | N6: 10 | O6: 0 | P6: 14 | Q6: 10 | R6: 10 | S6: 0 | T6: 18 | U6: 0 | V6: 0 | W6: 7 | X6: 7 | Y6: 7 | Z6: 7 | AA6: 10 | AB6: 10 | AC6: 8 | AD6: 0 | AE6: 0 | AF6: 0 | AG6: 7 | AH6: 7 | AI6: 7 | AJ6: 7 | AK6: 10 | AL6: -2 | AM6: 0
A7: OBAJEMU, DAVID TOYOSI | B7: 3 | C7: 18004409 | D7: 0 | E7: 0 | F7: V | G7: V | H7: V | I7: V | J7: V | K7: 0 | L7: 0 | M7: 0 | N7: 0 | O7: V | P7: V | Q7: 7 | R7: 7 | S7: 10 | T7: 0 | U7: 0 | V7: 10 | W7: 0 | X7: 0 | Y7: 7 | Z7: 7 | AA7: 7 | AB7: 7 | AC7: -2 | AD7: 0 | AE7: 10 | AF7: 10 | AG7: 0 | AH7: 0 | AI7: 7 | AJ7: 7 | AK7: 7 | AL7: 1 | AM7: 0
A8: OLOWO, ABIODUN | B8: 3 | C8: 18004523 | D8: 10 | E8: 0 | F8: 14 | G8: 10 | H8: 0 | I8: 14 | J8: 10 | K8: 12 | L8: 14 | M8: 0 | N8: 14 | O8: 10 | P8: 0 | Q8: 7 | R8: 7 | S8: 7 | T8: 5 | U8: 0 | V8: 7 | W8: 10 | X8: 10 | Y8: 0 | Z8: 0 | AA8: 7 | AB8: 7 | AC8: 1 | AD8: 0 | AE8: 7 | AF8: 7 | AG8: 10 | AH8: 10 | AI8: 0 | AJ8: 0 | AK8: 7 | AL8: 1 | AM8: 0
A9: ADRIYEN, ADEYEMI JOHN | B9: 3 | C9: 18004133 | D9: 7 | E9: 10 | F9: 10 | G9: 0 | H9: 0 | I9: 7 | J9: 7 | K9: -1 | L9: 10 | M9: 7 | N9: 7 | O9: 10 | P9: 10 | Q9: 0 | R9: 0 | S9: 7 | T9: 1 | U9: 0 | V9: 7 | W9: 7 | X9: 7 | Y9: 10 | Z9: 10 | AA9: 0 | AB9: 0 | AC9: 1 | AD9: 0 | AE9: 7 | AF9: 7 | AG9: 7 | AH9: 7 | AI9: 10 | AJ9: 10 | AK9: 0 | AL9: 8 | AM9: 0
A10: FAKEYE, DANIEL OLAOLUWA | B10: 3 | C10: 18004329 | D10: 0 | E10: 7 | F10: 7 | G10: 7 | H10: 7 | I10: 10 | J10: 10 | K10: 9 | L10: 7 | M10: 0 | N10: 0 | O10: 7 | P10: 7 | Q10: 7 | R10: 7 | S10: 10 | T10: -2 | U10: 0 | V10: 10 | W10: 0 | X10: 0 | Y10: 7 | Z10: 7 | AA10: 7 | AB10: 7 | AC10: -2 | AD10: 0 | AE10: 10 | AF10: 10 | AG10: 0 | AH10: 0 | AI10: 7 | AJ10: 7 | AK10: 7 | AL10: 1 | AM10: 0
A11: ALIYU RAHMON | B11: 3 | C11: 18000601 | D11: 7 | E11: 7 | F11: 7 | G11: 10 | H11: 10 | I11: 0 | J11: 0 | K11: 2 | L11: 7 | M11: 7 | N11: 7 | O11: 7 | P11: 7 | Q11: 10 | R11: 10 | S11: 0 | T11: 8 | U11: 0 | V11: 0 | W11: 7 | X11: 7 | Y11: 7 | Z11: 7 | AA11: 10 | AB11: 10 | AC11: 8 | AD11: 0 | AE11: 0 | AF11: 0 | AG11: 7 | AH11: 7 | AI11: 7 | AJ11: 7 | AK11: 10 | AL11: -2 | AM11: 0
A12: OGUNFUNWA, OLADAPO SAMUEL | B12: 3 | C12: 18004443 | D12: 10 | E12: 0 | F12: 0 | G12: 7 | H12: 7 | I12: 7 | J12: 7 | K12: 6 | L12: 0 | M12: 10 | N12: 10 | O12: 0 | P12: 0 | Q12: 7 | R12: 7 | S12: 7 | T12: 1 | U12: 0 | V12: 7 | W12: 10 | X12: 10 | Y12: 0 | Z12: 0 | AA12: 7 | AB12: 7 | AC12: 1 | AD12: 0 | AE12: 7 | AF12: 7 | AG12: 10 | AH12: 10 | AI12: 0 | AJ12: 0 | AK12: 7 | AL12: 1 | AM12: 0
A13: AYODELE, ADEKUNLE LAWRENCE | B13: 3 | C13: 18004252 | D13: 10 | E13: 0 | F13: 14 | G13: 10 | H13: 10 | I13: 0 | J13: 0 | K13: -2 | L13: 14 | M13: 7 | N13: 7 | O13: V | P13: V | Q13: V | R13: V | S13: V | T13: 14 | U13: 0 | V13: 0 | W13: 0 | X13: V | Y13: V | Z13: V | AA13: V | AB13: V | AC13: 0 | AD13: 0 | AE13: 0 | AF13: 0 | AG13: 14 | AH13: 10 | AI13: 0 | AJ13: 14 | AK13: 10 | AL13: 8 | AM13: 0
A14: ELIJAH, JEREMIAH | B14: 3 | C14: 18004314 | D14: 14 | E14: 10 | F14: 0 | G14: 7 | H14: 7 | I14: 10 | J14: 10 | K14: 26 | L14: 0 | M14: 0 | N14: 0 | O14: 14 | P14: 10 | Q14: 0 | R14: 14 | S14: 10 | T14: 8 | U14: 0 | V14: 0 | W14: 14 | X14: 10 | Y14: 0 | Z14: 14 | AA14: 10 | AB14: 0 | AC14: 8 | AD14: 0 | AE14: 14 | AF14: 10 | AG14: 0 | AH14: 14 | AI14: 10 | AJ14: 0 | AK14: 14 | AL14: 22 | AM14: 0
A15: KASARACHI, COLINS | B15: 3 | C15: 18008453 | D15: 0 | E15: 0 | F15: V | G15: 7 | H15: 7 | I15: 7 | J15: 7 | K15: -4 | L15: 0 | M15: 10 | N15: 10 | O15: 0 | P15: 14 | Q15: 10 | R15: 0 | S15: 14 | T15: 18 | U15: 0 | V15: 10 | W15: 0 | X15: 14 | Y15: 10 | Z15: 0 | AA15: 14 | AB15: 10 | AC15: 18 | AD15: 0 | AE15: 0 | AF15: 14 | AG15: 10 | AH15: 0 | AI15: 14 | AJ15: 10 | AK15: 0 | AL15: 8 | AM15: 0
A16: NWACHUKWU, PAUL | B16: 3 | C16: 18008456 | D16: 0 | E16: 14 | F16: 10 | G16: 0 | H16: 0 | I16: 7 | J16: 7 | K16: -4 | L16: 10 | M16: 7 | N16: 7 | O16: 10 | P16: 0 | Q16: 14 | R16: 10 | S16: 0 | T16: 8 | U16: 0 | V16: 14 | W16: 10 | X16: 0 | Y16: 14 | Z16: 10 | AA16: 0 | AB16: 14 | AC16: 22 | AD16: 0 | AE16: 10 | AF16: 0 | AG16: V | AH16: V | AI16: V | AJ16: V | AK16: V | AL16: 10 | AM16: 0
A17: NWOSU NNAMDI SIMON | B17: 3 | C17: 18008088 | D17: 10 | E17: 0 | F17: 0 | G17: 7 | H17: 7 | I17: 7 | J17: 7 | K17: 6 | L17: 0 | M17: 10 | N17: 10 | O17: 0 | P17: 0 | Q17: 7 | R17: 7 | S17: 7 | T17: 1 | U17: 0 | V17: 7 | W17: 10 | X17: 10 | Y17: 0 | Z17: 0 | AA17: 7 | AB17: 7 | AC17: 1 | AD17: 0 | AE17: 7 | AF17: 7 | AG17: 10 | AH17: 10 | AI17: 0 | AJ17: 0 | AK17: 7 | AL17: 1 | AM17: 0
A18: OSENI HABBEEB | B18: 3 | C18: 18008107 | D18: 0 | E18: 7 | F18: 7 | G18: 7 | H18: 7 | I18: 10 | J18: 10 | K18: 9 | L18: 7 | M18: 0 | N18: 0 | O18: 7 | P18: 7 | Q18: 7 | R18: 7 | S18: 10 | T18: -2 | U18: 0 | V18: 10 | W18: 0 | X18: 0 | Y18: 7 | Z18: 7 | AA18: 7 | AB18: 7 | AC18: -2 | AD18: 0 | AE18: 10 | AF18: 10 | AG18: 0 | AH18: 0 | AI18: 7 | AJ18: 7 | AK18: 7 | AL18: 1 | AM18: 0
A19: UMWENI, JOEL | B19: 3 | C19: 18008465 | D19: 7 | E19: 7 | F19: 7 | G19: 10 | H19: 10 | I19: 0 | J19: 0 | K19: 2 | L19: 7 | M19: 7 | N19: 7 | O19: 7 | P19: 7 | Q19: 10 | R19: 10 | S19: 0 | T19: 8 | U19: 0 | V19: 0 | W19: 7 | X19: 7 | Y19: 7 | Z19: 7 | AA19: 10 | AB19: 10 | AC19: 8 | AD19: 0 | AE19: 0 | AF19: 0 | AG19: 7 | AH19: 7 | AI19: 7 | AJ19: 7 | AK19: 10 | AL19: -2 | AM19: 0
A20: JAYEOBA, JOSHUA | B20: 3 | C20: 18008451 | D20: 7 | E20: 10 | F20: 10 | G20: 0 | H20: 0 | I20: 7 | J20: 7 | K20: -1 | L20: 10 | M20: 7 | N20: 7 | O20: 10 | P20: 10 | Q20: 0 | R20: 0 | S20: 7 | T20: 1 | U20: 0 | V20: 7 | W20: 7 | X20: 7 | Y20: 10 | Z20: 10 | AA20: 0 | AB20: 0 | AC20: 1 | AD20: 0 | AE20: 7 | AF20: 7 | AG20: 7 | AH20: 7 | AI20: 10 | AJ20: 10 | AK20: 0 | AL20: 8 | AM20: 0
A21: BADMUS , ADESHINA | B21: 3 | C21: 18004264 | D21: 10 | E21: 10 | F21: T | G21: T | H21: T | I21: 10 | J21: 10 | K21: 24 | L21: 0 | M21: 0 | N21: 0 | O21: T | P21: T | Q21: T | R21: T | S21: T | T21: 0 | U21: 0 | V21: 0 | W21: 0 | X21: T | Y21: T | Z21: T | AA21: T | AB21: T | AC21: 0 | AD21: 0 | AE21: 0 | AF21: 0 | AG21: T | AH21: T | AI21: T | AJ21: T | AK21: T | AL21: 0 | AM21: 0
A22: ADEGBOYEGA, KHABEER KOLAPO | B22: 3 | C22: 18004089 | D22: 0 | E22: 0 | F22: T | G22: T | H22: T | I22: T | J22: T | K22: 0 | L22: 0 | M22: 0 | N22: 0 | O22: T | P22: T | Q22: T | R22: T | S22: T | T22: 0 | U22: 0 | V22: 0 | W22: 0 | X22: T | Y22: T | Z22: T | AA22: T | AB22: T | AC22: 0 | AD22: 0 | AE22: 0 | AF22: 0 | AG22: T | AH22: T | AI22: T | AJ22: T | AK22: T | AL22: 0 | AM22: 0
A23: ADELIYI, OMOLADE OLUMIDE | B23: 4 | C23: 18004099 | D23: 10 | E23: 0 | F23: 0 | G23: 7 | H23: 7 | I23: 7 | J23: 7 | K23: 6 | L23: 0 | M23: 10 | N23: 10 | O23: O | P23: O | Q23: 7 | R23: 7 | S23: 7 | T23: 1 | U23: 0 | V23: 7 | W23: 10 | X23: 10 | Y23: O | Z23: O | AA23: 7 | AB23: 7 | AC23: 1 | AD23: 0 | AE23: 7 | AF23: 7 | AG23: 10 | AH23: 10 | AI23: O | AJ23: O | AK23: 7 | AL23: 1 | AM23: 0
A24: EMMANUEL, OGIDI JAMES | B24: 4 | C24: 18004316 | D24: 7 | E24: 10 | F24: 10 | G24: O | H24: O | I24: 7 | J24: 7 | K24: -1 | L24: 10 | M24: 7 | N24: 7 | O24: 10 | P24: 10 | Q24: O | R24: O | S24: 7 | T24: 1 | U24: 0 | V24: 7 | W24: 7 | X24: 7 | Y24: 10 | Z24: 10 | AA24: O | AB24: O | AC24: 1 | AD24: 0 | AE24: 7 | AF24: 7 | AG24: 7 | AH24: 7 | AI24: 10 | AJ24: 10 | AK24: O | AL24: 8 | AM24: 0
A25: FATOBA, ADENIYI JOHNSON | B25: 4 | C25: 18004342 | D25: O | E25: 7 | F25: 7 | G25: 7 | H25: 7 | I25: 10 | J25: 10 | K25: 9 | L25: 7 | M25: O | N25: Off Duty | O25: 7 | P25: 7 | Q25: 7 | R25: 7 | S25: 10 | T25: -2 | U25: 0 | V25: 10 | W25: O | X25: O | Y25: 7 | Z25: 7 | AA25: 7 | AB25: 7 | AC25: -2 | AD25: 0 | AE25: 10 | AF25: 10 | AG25: O | AH25: O | AI25: 7 | AJ25: 7 | AK25: 7 | AL25: 1 | AM25: 0
A26: OSAYEMI, OLADIMEJI | B26: 4 | C26: 18004562 | D26: 7 | E26: 7 | F26: 7 | G26: 10 | H26: 10 | I26: O | J26: O | K26: 2 | L26: 7 | M26: 7 | N26: 7 | O26: 7 | P26: 7 | Q26: 10 | R26: 10 | S26: O | T26: 8 | U26: 0 | V26: O | W26: 7 | X26: 7 | Y26: 7 | Z26: 7 | AA26: 10 | AB26: 10 | AC26: 8 | AD26: 0 | AE26: O | AF26: O | AG26: 7 | AH26: 7 | AI26: 7 | AJ26: 7 | AK26: 10 | AL26: -2 | AM26: 0
A27: ADEBAYO, OLUTAYO SOLOMON | B27: 4 | C27: 18004075 | D27: O | E27: 7 | F27: 7 | G27: 7 | H27: 7 | I27: 10 | J27: 10 | K27: 9 | L27: 7 | M27: O | N27: Off Duty | O27: 7 | P27: 7 | Q27: 7 | R27: 7 | S27: 10 | T27: -2 | U27: 0 | V27: 10 | W27: O | X27: O | Y27: 7 | Z27: 7 | AA27: 7 | AB27: 7 | AC27: -2 | AD27: 0 | AE27: 10 | AF27: 10 | AG27: O | AH27: O | AI27: 7 | AJ27: 7 | AK27: 7 | AL27: 1 | AM27: 0
A28: AKEJU, SUNDAY OLUSHOLA | B28: 4 | C28: 18004173 | D28: 7 | E28: 10 | F28: 10 | G28: O | H28: O | I28: 7 | J28: 7 | K28: -1 | L28: 10 | M28: 7 | N28: 7 | O28: 10 | P28: 10 | Q28: O | R28: O | S28: 7 | T28: 1 | U28: 0 | V28: 7 | W28: 7 | X28: 7 | Y28: 10 | Z28: 10 | AA28: O | AB28: O | AC28: 1 | AD28: 0 | AE28: 7 | AF28: 7 | AG28: 7 | AH28: 7 | AI28: 10 | AJ28: 10 | AK28: O | AL28: 8 | AM28: 0
A29: AKINMUSAYO, RAPHAEL OLUWOLE | B29: 4 | C29: 18004184 | D29: 7 | E29: 7 | F29: 7 | G29: 10 | H29: 10 | I29: Overtime | J29: O | K29: 2 | L29: 7 | M29: 7 | N29: 7 | O29: 7 | P29: 7 | Q29: 10 | R29: 10 | S29: O | T29: 8 | U29: 0 | V29: O | W29: 7 | X29: 7 | Y29: 7 | Z29: 7 | AA29: 10 | AB29: 10 | AC29: 8 | AD29: 0 | AE29: O | AF29: O | AG29: 7 | AH29: 7 | AI29: 7 | AJ29: 7 | AK29: 10 | AL29: -2 | AM29: 0
A30: ANI, OSMOND OSITADINMA | B30: 4 | C30: 18004223 | D30: 7 | E30: O | F30: O | G30: 7 | H30: 7 | I30: 7 | J30: 7 | K30: 3 | L30: 0 | M30: 10 | N30: 10 | O30: O | P30: O | Q30: 7 | R30: 7 | S30: 7 | T30: 1 | U30: 0 | V30: 7 | W30: 10 | X30: 10 | Y30: O | Z30: O | AA30: 7 | AB30: 7 | AC30: 1 | AD30: 0 | AE30: 7 | AF30: 7 | AG30: 10 | AH30: 10 | AI30: O | AJ30: O | AK30: 7 | AL30: 1 | AM30: 0
A31: ADEBONOJO, ABIODUN ADEDOYIN | B31: 4 | C31: 18004079 | D31: 7 | E31: 10 | F31: 10 | G31: O | H31: 10 | I31: Overtime | J31: 14 | K31: 9 | L31: 10 | M31: 10 | N31: Off Duty | O31: 14 | P31: 10 | Q31: O | R31: 14 | S31: 10 | T31: 18 | U31: 0 | V31: O | W31: 14 | X31: 10 | Y31: O | Z31: O | AA31: 7 | AB31: 7 | AC31: -2 | AD31: 0 | AE31: 7 | AF31: 7 | AG31: 10 | AH31: 10 | AI31: O | AJ31: O | AK31: 7 | AL31: 1 | AM31: 0
A32: AGBABIAKA, JOSHUA OLANI | B32: 4 | C32: 18004140 | D32: 7 | E32: 7 | F32: O | G32: V | H32: V | I32: V | J32: V | K32: 14 | L32: 0 | M32: V | N32: V | O32: V | P32: V | Q32: V | R32: V | S32: V | T32: 0 | U32: 0 | V32: V | W32: V | X32: V | Y32: 7 | Z32: 7 | AA32: 10 | AB32: 10 | AC32: 2 | AD32: 0 | AE32: O | AF32: O | AG32: 7 | AH32: 7 | AI32: 7 | AJ32: 7 | AK32: 10 | AL32: -2 | AM32: 0
A33: OGUNDARE, SUNKANMI .M. | B33: 4 | C33: 18004439 | D33: O | E33: 7 | F33: 7 | G33: 10 | H33: O | I33: 14 | J33: 10 | K33: 9 | L33: 7 | M33: O | N33: 14 | O33: 10 | P33: O | Q33: 14 | R33: 10 | S33: O | T33: 8 | U33: 0 | V33: 14 | W33: 10 | X33: O | Y33: 7 | Z33: 7 | AA33: 7 | AB33: 7 | AC33: 12 | AD33: 0 | AE33: 10 | AF33: 10 | AG33: O | AH33: O | AI33: 7 | AJ33: 7 | AK33: 7 | AL33: 1 | AM33: 0
A34: OSENI, AZEEZ GBENGA | B34: 4 | C34: 18004564 | D34: 10 | E34: O | F34: O | G34: 14 | H34: 14 | I34: 10 | J34: O | K34: 16 | L34: 0 | M34: 14 | N34: 10 | O34: O | P34: 14 | Q34: 10 | R34: O | S34: 14 | T34: 22 | U34: 0 | V34: 10 | W34: O | X34: 14 | Y34: 10 | Z34: 10 | AA34: O | AB34: O | AC34: 4 | AD34: 0 | AE34: 7 | AF34: 7 | AG34: 7 | AH34: 7 | AI34: 10 | AJ34: 10 | AK34: O | AL34: 8 | AM34: 0
A35: ADEGBOYE IDOWU | B35: 4 | C35: 18007020 | D35: 14 | E35: 7 | F35: 10 | G35: 10 | H35: O | I35: Overtime | J35: 7 | K35: 6 | L35: 10 | M35: 14 | N35: 10 | O35: 10 | P35: O | Q35: O | R35: 7 | S35: 7 | T35: 8 | U35: 0 | V35: 10 | W35: 10 | X35: O | Y35: O | Z35: 7 | AA35: 7 | AB35: 10 | AC35: 4 | AD35: 0 | AE35: 10 | AF35: O | AG35: O | AH35: 7 | AI35: 7 | AJ35: 10 | AK35: 10 | AL35: 4 | AM35: 0
A36: BELLO KEHINDE HASSAN | B36: 4 | C36: 18006993 | D36: 10 | E36: 10 | F36: O | G36: O | H36: 7 | I36: 7 | J36: 10 | K36: 12 | L36: 0 | M36: 10 | N36: Off Duty | O36: O | P36: 7 | Q36: 7 | R36: 10 | S36: 10 | T36: 4 | U36: 0 | V36: O | W36: O | X36: 7 | Y36: 7 | Z36: 10 | AA36: 10 | AB36: O | AC36: -6 | AD36: 0 | AE36: O | AF36: 7 | AG36: 7 | AH36: 10 | AI36: 10 | AJ36: O | AK36: O | AL36: -6 | AM36: 0
A37: OGUNBIYI MUYIWA DARE | B37: 4 | C37: 18006986 | D37: O | E37: O | F37: 7 | G37: 7 | H37: 10 | I37: 10 | J37: O | K37: -5 | L37: 7 | M37: O | N37: 7 | O37: 7 | P37: 10 | Q37: 10 | R37: O | S37: O | T37: -6 | U37: 0 | V37: 7 | W37: 7 | X37: 10 | Y37: 10 | Z37: O | AA37: O | AB37: 7 | AC37: 1 | AD37: 0 | AE37: 7 | AF37: 10 | AG37: 10 | AH37: O | AI37: O | AJ37: 7 | AK37: 7 | AL37: 1 | AM37: 0
A38: POPOOLA VERONICA | B38: 4 | C38: 18005749 | D38: O | E38: 7 | F38: 7 | G38: 7 | H38: 7 | I38: 7 | J38: 7 | K38: 3 | L38: 7 | M38: O | N38: 7 | O38: 7 | P38: 7 | Q38: 7 | R38: 7 | S38: 7 | T38: 2 | U38: 0 | V38: O | W38: 7 | X38: 7 | Y38: 7 | Z38: 7 | AA38: 7 | AB38: 7 | AC38: 2 | AD38: 0 | AE38: O | AF38: 7 | AG38: 7 | AH38: 7 | AI38: 7 | AJ38: 7 | AK38: 7 | AL38: 2 | AM38: 0
A39: AKANDE, OLUFEMI ADEMOLA | B39: 4 | C39: 18004170 | D39: 7 | E39: 10 | F39: 10 | G39: O | H39: O | I39: 7 | J39: 7 | K39: -1 | L39: 10 | M39: 7 | N39: 7 | O39: 10 | P39: 10 | Q39: O | R39: O | S39: 7 | T39: 1 | U39: 0 | V39: 7 | W39: 7 | X39: 7 | Y39: 10 | Z39: 10 | AA39: O | AB39: O | AC39: 1 | AD39: 0 | AE39: 7 | AF39: 7 | AG39: 7 | AH39: 7 | AI39: 10 | AJ39: 10 | AK39: O | AL39: 8 | AM39: 0
A40: AKINYEMI, OZIEGBE VINCENT | B40: 4 | C40: 18004198 | D40: O | E40: O | F40: 8 | G40: 8 | H40: 8 | I40: 14 | J40: 8 | K40: 6 | L40: 8 | M40: O | N40: Off Duty | O40: 8 | P40: 8 | Q40: 8 | R40: 8 | S40: 8 | T40: 0 | U40: 0 | V40: O | W40: O | X40: 8 | Y40: 8 | Z40: 8 | AA40: 8 | AB40: 8 | AC40: 0 | AD40: 0 | AE40: O | AF40: O | AG40: 8 | AH40: 8 | AI40: 8 | AJ40: 8 | AK40: 8 | AL40: 0 | AM40: 0
A41: MIRACLE CHIJOKE ALOZIE | B41: 4 | C41: 18008449 | D41: O | E41: 7 | F41: 7 | G41: 7 | H41: 7 | I41: 10 | J41: 10 | K41: 9 | L41: 7 | M41: O | N41: Off Duty | O41: 7 | P41: 7 | Q41: 7 | R41: 7 | S41: 10 | T41: -2 | U41: 0 | V41: 10 | W41: O | X41: O | Y41: 7 | Z41: 7 | AA41: 7 | AB41: 7 | AC41: -2 | AD41: 0 | AE41: 10 | AF41: 10 | AG41: O | AH41: O | AI41: 7 | AJ41: 7 | AK41: 7 | AL41: 1 | AM41: 0
...

Sheet Line 3
A1: Monthly Timesheet | BZ1: Nigerian Bottling Company | CA1: Nigerian Bottling Company | CB1: Monthly Timesheet Template
CB2: © 2016 Vertex42 LLC
A3: Function | B3: [Manufacturing] | I3: Holiday | R3: H
A4: Department | B4: [Production] | E4: Vacation | H4: V | J4: Overtime | M4: OT | R4: Examination Leave | V4: EL | AE4: Public Holidays
A5: Location | B5: [Lagos] | E5: Sick Leave | H5: SL | J5: Public Holidays | M5: PH | R5: Casual leave | V5: CAL
A6: Start Week Containing | B6: 44408 | E6: Maternity Leave | H6: ML | J6: Absentism | M6: AB | R6: Off Duty | V6: O
B7: Friday | C7: =MOD(MATCH(B7,{"Sunday";"Monday";"Tuesday";"Wednesday";"Thursday";"Friday";"Saturday"},0),7)+1 -> 7 | E7: Training | H7: T | J7: Compensation leave | M7: CL | R7: Exemption | V7: E | AJ7: Target | AO7: 1000000
AJ8: Actual | AO8: =CB45 -> 905353.42
A9: Total Week in the Month | E9: =IFERROR(COUNTIF(LINE8_PH,E11),0) -> 0 | F9: =IFERROR(COUNTIF(LINE8_PH,F11),0) -> 0 | G9: =IFERROR(COUNTIF(LINE8_PH,G11),0) -> 0 | H9: =IFERROR(COUNTIF(LINE8_PH,H11),0) -> 0 | I9: =IFERROR(COUNTIF(LINE8_PH,I11),0) -> 0 | J9: =IFERROR(COUNTIF(LINE8_PH,J11),0) -> 0 | K9: =IFERROR(COUNTIF(LINE8_PH,K11),0) -> 0 | L9: =SUM(G9:K9) -> 0 | M9: =COUNTIF(LINE8_PH,M11) -> 0 | Q9: =IFERROR(COUNTIF(LINE8_PH,Q11),0) -> 0 | R9: =IFERROR(COUNTIF(LINE8_PH,R11),0) -> 0 | S9: =IFERROR(COUNTIF(LINE8_PH,S11),0) -> 0 | T9: =IFERROR(COUNTIF(LINE8_PH,T11),0) -> 0 | U9: =IFERROR(COUNTIF(LINE8_PH,U11),0) -> 0 | V9: =IFERROR(COUNTIF(LINE8_PH,V11),0) -> 0 | W9: =IFERROR(COUNTIF(LINE8_PH,W11),0) -> 0 | X9: =SUM(S9:W9) -> 0 | Y9: =COUNTIF(LINE8_PH,Y11) -> 0 | AC9: =IFERROR(COUNTIF(LINE8_PH,AC11),0) -> 0 | AD9: =IFERROR(COUNTIF(LINE8_PH,AD11),0) -> 0 | AE9: =IFERROR(COUNTIF(LINE8_PH,AE11),0) -> 0 | AF9: =IFERROR(COUNTIF(LINE8_PH,AF11),0) -> 0 | AG9: =IFERROR(COUNTIF(LINE8_PH,AG11),0) -> 0 | AH9: =IFERROR(COUNTIF(LINE8_PH,AH11),0) -> 0 | AI9: =IFERROR(COUNTIF(LINE8_PH,AI11),0) -> 0 | AJ9: =SUM(AE9:AI9) -> 0 | AK9: =COUNTIF(LINE8_PH,AK11) -> 0 | AO9: =IFERROR(COUNTIF(LINE8_PH,AO11),0) -> 0 | AP9: =IFERROR(COUNTIF(LINE8_PH,AP11),0) -> 0 | AQ9: =IFERROR(COUNTIF(LINE8_PH,AQ11),0) -> 0 | AR9: =IFERROR(COUNTIF(LINE8_PH,AR11),0) -> 0 | AS9: =IFERROR(COUNTIF(LINE8_PH,AS11),0) -> 0 | AT9: =IFERROR(COUNTIF(LINE8_PH,AT11),0) -> 0 | AU9: =IFERROR(COUNTIF(LINE8_PH,AU11),0) -> 0 | AV9: =SUM(AQ9:AU9) -> 0 | AW9: =COUNTIF(LINE8_PH,AW11) -> 0 | BA9: =IFERROR(COUNTIF(LINE8_PH,BA11),0) -> 0 | BB9: =IFERROR(COUNTIF(LINE8_PH,BB11),0) -> 0 | BC9: =IFERROR(COUNTIF(LINE8_PH,BC11),0) -> 0 | BD9: =IFERROR(COUNTIF(LINE8_PH,BD11),0) -> 0 | BE9: =IFERROR(COUNTIF(LINE8_PH,BE11),0) -> 0 | BF9: =IFERROR(COUNTIF(LINE8_PH,BF11),0) -> 0 | BG9: =IFERROR(COUNTIF(LINE8_PH,BG11),0) -> 0 | BH9: =SUM(BC9:BG9) -> 0 | BI9: =COUNTIF(LINE8_PH,BI11) -> 0 | BM9: =IFERROR(COUNTIF(LINE8_PH,BM11),0) -> 0 | BN9: =IFERROR(COUNTIF(LINE8_PH,BN11),0) -> 0 | BO9: =IFERROR(COUNTIF(LINE8_PH,BO11),0) -> 0 | BP9: =IFERROR(COUNTIF(LINE8_PH,BP11),0) -> 0 | BQ9: =IFERROR(COUNTIF(LINE8_PH,BQ11),0) -> 0 | BR9: =IFERROR(COUNTIF(LINE8_PH,BR11),0) -> 0 | BS9: =IFERROR(COUNTIF(LINE8_PH,BS11),0) -> 0 | BT9: =SUM(BO9:BS9) -> 0 | BU9: =COUNTIF(LINE8_PH,BU11) -> 0 | BZ9: =COUNTIF(LINE8_PH,BZ11) -> 0
E10: =IF(OR(C11="",MONTH(E11)<>MONTH(C11)),TEXT(E11,"mmm"),"") -> Jul | F10: =IF(OR(E11="",MONTH(F11)<>MONTH(E11)),TEXT(F11,"mmm"),"") -> Aug | G10: =IF(OR(F11="",MONTH(G11)<>MONTH(F11)),TEXT(G11,"mmm"),"") | H10: =IF(OR(G11="",MONTH(H11)<>MONTH(G11)),TEXT(H11,"mmm"),"") | I10: =IF(OR(H11="",MONTH(I11)<>MONTH(H11)),TEXT(I11,"mmm"),"") | J10: =IF(OR(I11="",MONTH(J11)<>MONTH(I11)),TEXT(J11,"mmm"),"") | K10: =IF(OR(J11="",MONTH(K11)<>MONTH(J11)),TEXT(K11,"mmm"),"") | Q10: =IF(OR(K11="",MONTH(Q11)<>MONTH(K11)),TEXT(Q11,"mmm"),"") | R10: =IF(OR(Q11="",MONTH(R11)<>MONTH(Q11)),TEXT(R11,"mmm"),"") | S10: =IF(OR(R11="",MONTH(S11)<>MONTH(R11)),TEXT(S11,"mmm"),"") | T10: =IF(OR(S11="",MONTH(T11)<>MONTH(S11)),TEXT(T11,"mmm"),"") | U10: =IF(OR(T11="",MONTH(U11)<>MONTH(T11)),TEXT(U11,"mmm"),"") | V10: =IF(OR(U11="",MONTH(V11)<>MONTH(U11)),TEXT(V11,"mmm"),"") | W10: =IF(OR(V11="",MONTH(W11)<>MONTH(V11)),TEXT(W11,"mmm"),"") | AC10: =IF(OR(W11="",MONTH(AC11)<>MONTH(W11)),TEXT(AC11,"mmm"),"") | AD10: =IF(OR(AC11="",MONTH(AD11)<>MONTH(AC11)),TEXT(AD11,"mmm"),"") | AE10: =IF(OR(AD11="",MONTH(AE11)<>MONTH(AD11)),TEXT(AE11,"mmm"),"") | AF10: =IF(OR(AE11="",MONTH(AF11)<>MONTH(AE11)),TEXT(AF11,"mmm"),"") | AG10: =IF(OR(AF11="",MONTH(AG11)<>MONTH(AF11)),TEXT(AG11,"mmm"),"") | AH10: =IF(OR(AG11="",MONTH(AH11)<>MONTH(AG11)),TEXT(AH11,"mmm"),"") | AI10: =IF(OR(AH11="",MONTH(AI11)<>MONTH(AH11)),TEXT(AI11,"mmm"),"") | AO10: =IF(OR(AI11="",MONTH(AO11)<>MONTH(AI11)),TEXT(AO11,"mmm"),"") | AP10: =IF(OR(AO11="",MONTH(AP11)<>MONTH(AO11)),TEXT(AP11,"mmm"),"") | AQ10: =IF(OR(AP11="",MONTH(AQ11)<>MONTH(AP11)),TEXT(AQ11,"mmm"),"") | AR10: =IF(OR(AQ11="",MONTH(AR11)<>MONTH(AQ11)),TEXT(AR11,"mmm"),"") | AS10: =IF(OR(AR11="",MONTH(AS11)<>MONTH(AR11)),TEXT(AS11,"mmm"),"") | AT10: =IF(OR(AS11="",MONTH(AT11)<>MONTH(AS11)),TEXT(AT11,"mmm"),"") | AU10: =IF(OR(AT11="",MONTH(AU11)<>MONTH(AT11)),TEXT(AU11,"mmm"),"") | BA10: =IF(OR(AU11="",MONTH(BA11)<>MONTH(AU11)),TEXT(BA11,"mmm"),"") | BM10: =IF(OR(BG11="",MONTH(BM11)<>MONTH(BG11)),TEXT(BM11,"mmm"),"")
E11: =B6 -> 44408 | F11: =E11+1 -> 44409 | G11: =F11+1 -> 44410 | H11: =G11+1 -> 44411 | I11: =H11+1 -> 44412 | J11: =I11+1 -> 44413 | K11: =J11+1 -> 44414 | Q11: =K11+1 -> 44415 | R11: =Q11+1 -> 44416 | S11: =R11+1 -> 44417 | T11: =S11+1 -> 44418 | U11: =T11+1 -> 44419 | V11: =U11+1 -> 44420 | W11: =V11+1 -> 44421 | AC11: =W11+1 -> 44422 | AD11: =AC11+1 -> 44423 | AE11: =AD11+1 -> 44424 | AF11: =AE11+1 -> 44425 | AG11: =AF11+1 -> 44426 | AH11: =AG11+1 -> 44427 | AI11: =AH11+1 -> 44428 | AO11: =AI11+1 -> 44429 | AP11: =AO11+1 -> 44430 | AQ11: =AP11+1 -> 44431 | AR11: =AQ11+1 -> 44432 | AS11: =AR11+1 -> 44433 | AT11: =AS11+1 -> 44434 | AU11: =AT11+1 -> 44435 | BA11: =AU11+1 -> 44436 | BB11: =BA11+1 -> 44437 | BC11: =BB11+1 -> 44438 | BD11: =BC11+1 -> 44439 | BE11: =BD11+1 -> 44440 | BF11: =BE11+1 -> 44441 | BG11: =BF11+1 -> 44442 | BM11: =BG11+1 -> 44443 | BN11: =BM11+1 -> 44444 | BO11: =BN11+1 -> 44445 | BP11: =BO11+1 -> 44446 | BQ11: =BP11+1 -> 44447 | BR11: =BQ11+1 -> 44448 | BS11: =BR11+1 -> 44449
A12: Employee Name | B12: Position | C12: ID | D12: Basic | E12: =CHOOSE(WEEKDAY(E11,1),"Su","M","Tu","W","Th","F","Sa") -> Sa | F12: =CHOOSE(WEEKDAY(F11,1),"Su","M","Tu","W","Th","F","Sa") -> Su | G12: =CHOOSE(WEEKDAY(G11,1),"Su","M","Tu","W","Th","F","Sa") -> M | H12: =CHOOSE(WEEKDAY(H11,1),"Su","M","Tu","W","Th","F","Sa") -> Tu | I12: =CHOOSE(WEEKDAY(I11,1),"Su","M","Tu","W","Th","F","Sa") -> W | J12: =CHOOSE(WEEKDAY(J11,1),"Su","M","Tu","W","Th","F","Sa") -> Th | K12: =CHOOSE(WEEKDAY(K11,1),"Su","M","Tu","W","Th","F","Sa") -> F | L12: OT | M12: PH | Q12: =CHOOSE(WEEKDAY(Q11,1),"Su","M","Tu","W","Th","F","Sa") -> Sa | R12: =CHOOSE(WEEKDAY(R11,1),"Su","M","Tu","W","Th","F","Sa") -> Su | S12: =CHOOSE(WEEKDAY(S11,1),"Su","M","Tu","W","Th","F","Sa") -> M | T12: =CHOOSE(WEEKDAY(T11,1),"Su","M","Tu","W","Th","F","Sa") -> Tu | U12: =CHOOSE(WEEKDAY(U11,1),"Su","M","Tu","W","Th","F","Sa") -> W | V12: =CHOOSE(WEEKDAY(V11,1),"Su","M","Tu","W","Th","F","Sa") -> Th | W12: =CHOOSE(WEEKDAY(W11,1),"Su","M","Tu","W","Th","F","Sa") -> F | X12: OT | Y12: PH | AC12: =CHOOSE(WEEKDAY(AC11,1),"Su","M","Tu","W","Th","F","Sa") -> Sa | AD12: =CHOOSE(WEEKDAY(AD11,1),"Su","M","Tu","W","Th","F","Sa") -> Su | AE12: =CHOOSE(WEEKDAY(AE11,1),"Su","M","Tu","W","Th","F","Sa") -> M | AF12: =CHOOSE(WEEKDAY(AF11,1),"Su","M","Tu","W","Th","F","Sa") -> Tu | AG12: =CHOOSE(WEEKDAY(AG11,1),"Su","M","Tu","W","Th","F","Sa") -> W | AH12: =CHOOSE(WEEKDAY(AH11,1),"Su","M","Tu","W","Th","F","Sa") -> Th | AI12: =CHOOSE(WEEKDAY(AI11,1),"Su","M","Tu","W","Th","F","Sa") -> F | AJ12: OT | AK12: PH | AO12: =CHOOSE(WEEKDAY(AO11,1),"Su","M","Tu","W","Th","F","Sa") -> Sa | AP12: =CHOOSE(WEEKDAY(AP11,1),"Su","M","Tu","W","Th","F","Sa") -> Su | AQ12: =CHOOSE(WEEKDAY(AQ11,1),"Su","M","Tu","W","Th","F","Sa") -> M | AR12: =CHOOSE(WEEKDAY(AR11,1),"Su","M","Tu","W","Th","F","Sa") -> Tu | AS12: =CHOOSE(WEEKDAY(AS11,1),"Su","M","Tu","W","Th","F","Sa") -> W | AT12: =CHOOSE(WEEKDAY(AT11,1),"Su","M","Tu","W","Th","F","Sa") -> Th | AU12: =CHOOSE(WEEKDAY(AU11,1),"Su","M","Tu","W","Th","F","Sa") -> F | AV12: OT | AW12: PH | BA12: =CHOOSE(WEEKDAY(BA11,1),"Su","M","Tu","W","Th","F","Sa") -> Sa | BB12: =CHOOSE(WEEKDAY(BB11,1),"Su","M","Tu","W","Th","F","Sa") -> Su | BC12: =CHOOSE(WEEKDAY(BC11,1),"Su","M","Tu","W","Th","F","Sa") -> M | BD12: =CHOOSE(WEEKDAY(BD11,1),"Su","M","Tu","W","Th","F","Sa") -> Tu | BE12: =CHOOSE(WEEKDAY(BE11,1),"Su","M","Tu","W","Th","F","Sa") -> W | BF12: =CHOOSE(WEEKDAY(BF11,1),"Su","M","Tu","W","Th","F","Sa") -> Th | BG12: =CHOOSE(WEEKDAY(BG11,1),"Su","M","Tu","W","Th","F","Sa") -> F | BH12: OT | BI12: PH | BM12: =CHOOSE(WEEKDAY(BM11,1),"Su","M","Tu","W","Th","F","Sa") -> Sa | BN12: =CHOOSE(WEEKDAY(BN11,1),"Su","M","Tu","W","Th","F","Sa") -> Su | BO12: =CHOOSE(WEEKDAY(BO11,1),"Su","M","Tu","W","Th","F","Sa") -> M | BP12: =CHOOSE(WEEKDAY(BP11,1),"Su","M","Tu","W","Th","F","Sa") -> Tu | BQ12: =CHOOSE(WEEKDAY(BQ11,1),"Su","M","Tu","W","Th","F","Sa") -> W | BR12: =CHOOSE(WEEKDAY(BR11,1),"Su","M","Tu","W","Th","F","Sa") -> Th | BS12: =CHOOSE(WEEKDAY(BS11,1),"Su","M","Tu","W","Th","F","Sa") -> F | BT12: OT | BU12: PH | BZ12: Total OT Hrs | CA12: Total PH Hrs | CB12: OT Amount | CC12: OD rate | CD12: PH rate
B13: 3 | C13: 18004071 | D13: =IF(C13="",0,VLOOKUP(C13,Conf!A:D,4,FALSE)) -> 160861.75 | E13: 7 | F13: 7 | G13: 10 | H13: 10 | I13: 0 | J13: 0 | K13: 7 | L13: =IF(AND(O13<0,N13>0),0,(IF(AND(P13<0,BY13>1),0,IF(AND(E13="",F13="",G13="",H13="",I13="",J13="",K13=""),0,IF(AND(E13="",F13="",G13="",H13="",I13="",J13="",K13=""),0,SUM(E13:K13)-40-M13)+(COUNTIF(G13:K13,"v")*8)+(COUNTIF(G13:K13,"sl")*8)+(COUNTIF(G13:K13,"ml")*8)+(COUNTIF(G13:K13,"t")*8)+(COUNTIF(G13:K13,"cl")*8)+(COUNTIF(G13:K13,"el")*8)+(COUNTIF(G13:K13,"cal")*8)+(COUNTIF(G13:K13,"E")*8)+($L$9*8))+IF($G$9=1,IF(OR(G13="sl",G13="v",G13="ml",G13="e",G13="t",G13="cl",G13="cal"),-8,0))+IF($H$9=1,IF(OR(H13="sl",H13="v",H13="ml",H13="e",H13="t",H13="cl",H13="cal"),-8,0))+IF($I$9=1,IF(OR(I13="sl",I13="v",I13="ml",I13="e",I13="t",I13="cl",I13="cal"),-8,0))+IF($J$9=1,IF(OR(J13="sl",J13="v",J13="ml",J13="e",J13="t",J13="cl",J13="cal"),-8,0))+IF($K$9=1,IF(OR(K13="sl",K13="v",K13="ml",K13="e",K13="t",K13="cl",K13="cal"),-8,0))))) -> 1 | M13: =SUMIF(E$9:K$9,1,E13:K13) -> 0 | N13: =COUNTIF(E13:F13,14)+IF(AND($G$9=0,G13=14),1,0)+IF(AND($H$9=0,H13=14),1,0)+IF(AND($I$9=0,I13=14),1,0)+IF(AND($J$9=0,J13=14),1,0)+IF(AND($K$9=0,K13=14),1,0) -> 0 | O13: =IF(AND(P13<0,BY13>1),0,IF(AND(E13="",F13="",G13="",H13="",I13="",J13="",K13=""),0,IF(AND(E13="",F13="",G13="",H13="",I13="",J13="",K13=""),0,SUM(E13:K13)-40-M13)+(COUNTIF(G13:K13,"v")*8)+(COUNTIF(G13:K13,"sl")*8)+(COUNTIF(G13:K13,"ml")*8)+(COUNTIF(G13:K13,"t")*8)+(COUNTIF(G13:K13,"cl")*8)+(COUNTIF(G13:K13,"el")*8)+(COUNTIF(G13:K13,"cal")*8)+(COUNTIF(G13:K13,"E")*8)+($L$9*8))+IF($G$9=1,IF(OR(G13="sl",G13="v",G13="ml",G13="e",G13="t",G13="cl",G13="cal"),-8,0))+IF($H$9=1,IF(OR(H13="sl",H13="v",H13="ml",H13="e",H13="t",H13="cl",H13="cal"),-8,0))+IF($I$9=1,IF(OR(I13="sl",I13="v",I13="ml",I13="e",I13="t",I13="cl",I13="cal"),-8,0))+IF($J$9=1,IF(OR(J13="sl",J13="v",J13="ml",J13="e",J13="t",J13="cl",J13="cal"),-8,0))+IF($K$9=1,IF(OR(K13="sl",K13="v",K13="ml",K13="e",K13="t",K13="cl",K13="cal"),-8,0))) -> 1 | P13: =IF(AND(E13="",F13="",G13="",H13="",I13="",J13="",K13=""),0,IF(AND(E13="",F13="",G13="",H13="",I13="",J13="",K13=""),0,SUM(E13:K13)-40-M13)+(COUNTIF(G13:K13,"v")*8)+(COUNTIF(G13:K13,"sl")*8)+(COUNTIF(G13:K13,"ml")*8)+(COUNTIF(G13:K13,"t")*8)+(COUNTIF(G13:K13,"cl")*8)+(COUNTIF(G13:K13,"el")*8)+(COUNTIF(G13:K13,"cal")*8)+(COUNTIF(G13:K13,"E")*8)+($L$9*8))+IF($G$9=1,IF(OR(G13="sl",G13="v",G13="ml",G13="e",G13="t",G13="cl",G13="cal"),-8,0))+IF($H$9=1,IF(OR(H13="sl",H13="v",H13="ml",H13="e",H13="t",H13="cl",H13="cal"),-8,0))+IF($I$9=1,IF(OR(I13="sl",I13="v",I13="ml",I13="e",I13="t",I13="cl",I13="cal"),-8,0))+IF($J$9=1,IF(OR(J13="sl",J13="v",J13="ml",J13="e",J13="t",J13="cl",J13="cal"),-8,0))+IF($K$9=1,IF(OR(K13="sl",K13="v",K13="ml",K13="e",K13="t",K13="cl",K13="cal"),-8,0)) -> 1 | Q13: 7 | R13: 7 | S13: 10 | T13: 0 | U13: 14 | V13: 10 | W13: 0 | X13: =IF(AND(AA13<0,Z13>0),0,(IF(AND(AB13<0,BY13>1),0,IF(AND(Q13="",R13="",S13="",T13="",U13="",V13="",W13=""),0,IF(AND(Q13="",R13="",S13="",T13="",U13="",V13="",W13=""),0,SUM(Q13:W13)-40-Y13)+(COUNTIF(S13:W13,"v")*8)+(COUNTIF(S13:W13,"sl")*8)+(COUNTIF(S13:W13,"ml")*8)+(COUNTIF(S13:W13,"t")*8)+(COUNTIF(S13:W13,"cl")*8)+(COUNTIF(S13:W13,"el")*8)+(COUNTIF(S13:W13,"cal")*8)+(COUNTIF(S13:W13,"E")*8)+($X$9*8))+IF($S$9=1,IF(OR(S13="sl",S13="v",S13="ml",S13="e",S13="t",S13="cl",S13="cal"),-8,0))+IF($T$9=1,IF(OR(T13="sl",T13="v",T13="ml",T13="e",T13="t",T13="cl",T13="cal"),-8,0))+IF($U$9=1,IF(OR(U13="sl",U13="v",U13="ml",U13="e",U13="t",U13="cl",U13="cal"),-8,0))+IF($V$9=1,IF(OR(V13="sl",V13="v",V13="ml",V13="e",V13="t",V13="cl",V13="cal"),-8,0))+IF($W$9=1,IF(OR(W13="sl",W13="v",W13="ml",W13="e",W13="t",W13="cl",W13="cal"),-8,0))))) -> 8 | Y13: =SUMIF(Q$9:W$9,1,Q13:W13) -> 0 | Z13: =COUNTIF(Q13:R13,14)+IF(AND($S$9=0,S13=14),1,0)+IF(AND($T$9=0,T13=14),1,0)+IF(AND($U$9=0,U13=14),1,0)+IF(AND($V$9=0,V13=14),1,0)+IF(AND($W$9=0,W13=14),1,0) -> 1 | AA13: =IF(AND(AB13<0,BY13>1),0,IF(AND(Q13="",R13="",S13="",T13="",U13="",V13="",W13=""),0,IF(AND(Q13="",R13="",S13="",T13="",U13="",V13="",W13=""),0,SUM(Q13:W13)-40-Y13)+(COUNTIF(S13:W13,"v")*8)+(COUNTIF(S13:W13,"sl")*8)+(COUNTIF(S13:W13,"ml")*8)+(COUNTIF(S13:W13,"t")*8)+(COUNTIF(S13:W13,"cl")*8)+(COUNTIF(S13:W13,"el")*8)+(COUNTIF(S13:W13,"cal")*8)+(COUNTIF(S13:W13,"E")*8)+($X$9*8))+IF($S$9=1,IF(OR(S13="sl",S13="v",S13="ml",S13="e",S13="t",S13="cl",S13="cal"),-8,0))+IF($T$9=1,IF(OR(T13="sl",T13="v",T13="ml",T13="e",T13="t",T13="cl",T13="cal"),-8,0))+IF($U$9=1,IF(OR(U13="sl",U13="v",U13="ml",U13="e",U13="t",U13="cl",U13="cal"),-8,0))+IF($V$9=1,IF(OR(V13="sl",V13="v",V13="ml",V13="e",V13="t",V13="cl",V13="cal"),-8,0))+IF($W$9=1,IF(OR(W13="sl",W13="v",W13="ml",W13="e",W13="t",W13="cl",W13="cal"),-8,0))) -> 8 | AB13: =IF(AND(Q13="",R13="",S13="",T13="",U13="",V13="",W13=""),0,IF(AND(Q13="",R13="",S13="",T13="",U13="",V13="",W13=""),0,SUM(Q13:W13)-40-Y13)+(COUNTIF(S13:W13,"v")*8)+(COUNTIF(S13:W13,"sl")*8)+(COUNTIF(S13:W13,"ml")*8)+(COUNTIF(S13:W13,"t")*8)+(COUNTIF(S13:W13,"cl")*8)+(COUNTIF(S13:W13,"el")*8)+(COUNTIF(S13:W13,"cal")*8)+(COUNTIF(S13:W13,"E")*8)+($X$9*8))+IF($S$9=1,IF(OR(S13="sl",S13="v",S13="ml",S13="e",S13="t",S13="cl",S13="cal"),-8,0))+IF($T$9=1,IF(OR(T13="sl",T13="v",T13="ml",T13="e",T13="t",T13="cl",T13="cal"),-8,0))+IF($U$9=1,IF(OR(U13="sl",U13="v",U13="ml",U13="e",U13="t",U13="cl",U13="cal"),-8,0))+IF($V$9=1,IF(OR(V13="sl",V13="v",V13="ml",V13="e",V13="t",V13="cl",V13="cal"),-8,0))+IF($W$9=1,IF(OR(W13="sl",W13="v",W13="ml",W13="e",W13="t",W13="cl",W13="cal"),-8,0)) -> 8 | AC13: 14 | AD13: 10 | AE13: 0 | AF13: 0 | AG13: 7 | AH13: 7 | AI13: 14 | AJ13: =IF(AND(AM13<0,AL13>0),0,(IF(AND(AN13<0,BY13>1),0,IF(AND(AC13="",AD13="",AE13="",AF13="",AG13="",AH13="",AI13=""),0,IF(AND(AC13="",AD13="",AE13="",AF13="",AG13="",AH13="",AI13=""),0,SUM(AC13:AI13)-40-AK13)+(COUNTIF(AE13:AI13,"v")*8)+(COUNTIF(AE13:AI13,"sl")*8)+(COUNTIF(AE13:AI13,"ml")*8)+(COUNTIF(AE13:AI13,"t")*8)+(COUNTIF(AE13:AI13,"cl")*8)+(COUNTIF(AE13:AI13,"el")*8)+(COUNTIF(AE13:AI13,"cal")*8)+(COUNTIF(AE13:AI13,"E")*8)+($AJ$9*8))+IF($AE$9=1,IF(OR(AE13="sl",AE13="v",AE13="ml",AE13="e",AE13="t",AE13="cl",AE13="cal"),-8,0))+IF($AF$9=1,IF(OR(AF13="sl",AF13="v",AF13="ml",AF13="e",AF13="t",AF13="cl",AF13="cal"),-8,0))+IF($AG$9=1,IF(OR(AG13="sl",AG13="v",AG13="ml",AG13="e",AG13="t",AG13="cl",AG13="cal"),-8,0))+IF($AH$9=1,IF(OR(AH13="sl",AH13="v",AH13="ml",AH13="e",AH13="t",AH13="cl",AH13="cal"),-8,0))+IF($AI$9=1,IF(OR(AI13="sl",AI13="v",AI13="ml",AI13="e",AI13="t",AI13="cl",AI13="cal"),-8,0))))) -> 12 | AK13: =SUMIF(AC$9:AI$9,1,AC13:AI13) -> 0 | AL13: =COUNTIF(AC13:AD13,14)+IF(AND($AE$9=0,AE13=14),1,0)+IF(AND($AF$9=0,AF13=14),1,0)+IF(AND($AG$9=0,AG13=14),1,0)+IF(AND($AH$9=0,AH13=14),1,0)+IF(AND($AI$9=0,AI13=14),1,0) -> 2 | AM13: =IF(AND(AN13<0,BY13>1),0,IF(AND(AC13="",AD13="",AE13="",AF13="",AG13="",AH13="",AI13=""),0,IF(AND(AC13="",AD13="",AE13="",AF13="",AG13="",AH13="",AI13=""),0,SUM(AC13:AI13)-40-AK13)+(COUNTIF(AE13:AI13,"v")*8)+(COUNTIF(AE13:AI13,"sl")*8)+(COUNTIF(AE13:AI13,"ml")*8)+(COUNTIF(AE13:AI13,"t")*8)+(COUNTIF(AE13:AI13,"cl")*8)+(COUNTIF(AE13:AI13,"el")*8)+(COUNTIF(AE13:AI13,"cal")*8)+(COUNTIF(AE13:AI13,"E")*8)+($AJ$9*8))+IF($AE$9=1,IF(OR(AE13="sl",AE13="v",AE13="ml",AE13="e",AE13="t",AE13="cl",AE13="cal"),-8,0))+IF($AF$9=1,IF(OR(AF13="sl",AF13="v",AF13="ml",AF13="e",AF13="t",AF13="cl",AF13="cal"),-8,0))+IF($AG$9=1,IF(OR(AG13="sl",AG13="v",AG13="ml",AG13="e",AG13="t",AG13="cl",AG13="cal"),-8,0))+IF($AH$9=1,IF(OR(AH13="sl",AH13="v",AH13="ml",AH13="e",AH13="t",AH13="cl",AH13="cal"),-8,0))+IF($AI$9=1,IF(OR(AI13="sl",AI13="v",AI13="ml",AI13="e",AI13="t",AI13="cl",AI13="cal"),-8,0))) -> 12 | AN13: =IF(AND(AC13="",AD13="",AE13="",AF13="",AG13="",AH13="",AI13=""),0,IF(AND(AC13="",AD13="",AE13="",AF13="",AG13="",AH13="",AI13=""),0,SUM(AC13:AI13)-40-AK13)+(COUNTIF(AE13:AI13,"v")*8)+(COUNTIF(AE13:AI13,"sl")*8)+(COUNTIF(AE13:AI13,"ml")*8)+(COUNTIF(AE13:AI13,"t")*8)+(COUNTIF(AE13:AI13,"cl")*8)+(COUNTIF(AE13:AI13,"el")*8)+(COUNTIF(AE13:AI13,"cal")*8)+(COUNTIF(AE13:AI13,"E")*8)+($AJ$9*8))+IF($AE$9=1,IF(OR(AE13="sl",AE13="v",AE13="ml",AE13="e",AE13="t",AE13="cl",AE13="cal"),-8,0))+IF($AF$9=1,IF(OR(AF13="sl",AF13="v",AF13="ml",AF13="e",AF13="t",AF13="cl",AF13="cal"),-8,0))+IF($AG$9=1,IF(OR(AG13="sl",AG13="v",AG13="ml",AG13="e",AG13="t",AG13="cl",AG13="cal"),-8,0))+IF($AH$9=1,IF(OR(AH13="sl",AH13="v",AH13="ml",AH13="e",AH13="t",AH13="cl",AH13="cal"),-8,0))+IF($AI$9=1,IF(OR(AI13="sl",AI13="v",AI13="ml",AI13="e",AI13="t",AI13="cl",AI13="cal"),-8,0)) -> 12 | AO13: 10 | AP13: 0 | AQ13: 14 | AR13: 10 | AS13: 0 | AT13: 14 | AU13: 10 | AV13: =IF(AND(AY13<0,AX13>0),0,(IF(AND(AZ13<0,BY13>1),0,IF(AND(AO13="",AP13="",AQ13="",AR13="",AS13="",AT13="",AU13=""),0,IF(AND(AO13="",AP13="",AQ13="",AR13="",AS13="",AT13="",AU13=""),0,SUM(AO13:AU13)-40-AW13)+(COUNTIF(AQ13:AU13,"v")*8)+(COUNTIF(AQ13:AU13,"sl")*8)+(COUNTIF(AQ13:AU13,"ml")*8)+(COUNTIF(AQ13:AU13,"t")*8)+(COUNTIF(AQ13:AU13,"cl")*8)+(COUNTIF(AQ13:AU13,"el")*8)+(COUNTIF(AQ13:AU13,"cal")*8)+(COUNTIF(AQ13:AU13,"E")*8)+($AV$9*8))+IF($AQ$9=1,IF(OR(AQ13="sl",AQ13="v",AQ13="ml",AQ13="e",AQ13="t",AQ13="cl",AQ13="cal"),-8,0))+IF($AR$9=1,IF(OR(AR13="sl",AR13="v",AR13="ml",AR13="e",AR13="t",AR13="cl",AR13="cal"),-8,0))+IF($AS$9=1,IF(OR(AS13="sl",AS13="v",AS13="ml",AS13="e",AS13="t",AS13="cl",AS13="cal"),-8,0))+IF($AT$9=1,IF(OR(AT13="sl",AT13="v",AT13="ml",AT13="e",AT13="t",AT13="cl",AT13="cal"),-8,0))+IF($AU$9=1,IF(OR(AU13="sl",AU13="v",AU13="ml",AU13="e",AU13="t",AU13="cl",AU13="cal"),-8,0))))) -> 18 | AW13: =SUMIF(AO$9:AU$9,1,AO13:AU13) -> 0 | AX13: =COUNTIF(AO13:AP13,14)+IF(AND($AQ$9=0,AQ13=14),1,0)+IF(AND($AR$9=0,AR13=14),1,0)+IF(AND($AS$9=0,AS13=14),1,0)+IF(AND($AT$9=0,AT13=14),1,0)+IF(AND($AU$9=0,AU13=14),1,0) -> 2 | AY13: =IF(AND(AZ13<0,BY13>1),0,IF(AND(AO13="",AP13="",AQ13="",AR13="",AS13="",AT13="",AU13=""),0,IF(AND(AO13="",AP13="",AQ13="",AR13="",AS13="",AT13="",AU13=""),0,SUM(AO13:AU13)-40-AW13)+(COUNTIF(AQ13:AU13,"v")*8)+(COUNTIF(AQ13:AU13,"sl")*8)+(COUNTIF(AQ13:AU13,"ml")*8)+(COUNTIF(AQ13:AU13,"t")*8)+(COUNTIF(AQ13:AU13,"cl")*8)+(COUNTIF(AQ13:AU13,"el")*8)+(COUNTIF(AQ13:AU13,"cal")*8)+(COUNTIF(AQ13:AU13,"E")*8)+($AV$9*8))+IF($AQ$9=1,IF(OR(AQ13="sl",AQ13="v",AQ13="ml",AQ13="e",AQ13="t",AQ13="cl",AQ13="cal"),-8,0))+IF($AR$9=1,IF(OR(AR13="sl",AR13="v",AR13="ml",AR13="e",AR13="t",AR13="cl",AR13="cal"),-8,0))+IF($AS$9=1,IF(OR(AS13="sl",AS13="v",AS13="ml",AS13="e",AS13="t",AS13="cl",AS13="cal"),-8,0))+IF($AT$9=1,IF(OR(AT13="sl",AT13="v",AT13="ml",AT13="e",AT13="t",AT13="cl",AT13="cal"),-8,0))+IF($AU$9=1,IF(OR(AU13="sl",AU13="v",AU13="ml",AU13="e",AU13="t",AU13="cl",AU13="cal"),-8,0))) -> 18 | AZ13: =IF(AND(AO13="",AP13="",AQ13="",AR13="",AS13="",AT13="",AU13=""),0,IF(AND(AO13="",AP13="",AQ13="",AR13="",AS13="",AT13="",AU13=""),0,SUM(AO13:AU13)-40-AW13)+(COUNTIF(AQ13:AU13,"v")*8)+(COUNTIF(AQ13:AU13,"sl")*8)+(COUNTIF(AQ13:AU13,"ml")*8)+(COUNTIF(AQ13:AU13,"t")*8)+(COUNTIF(AQ13:AU13,"cl")*8)+(COUNTIF(AQ13:AU13,"el")*8)+(COUNTIF(AQ13:AU13,"cal")*8)+(COUNTIF(AQ13:AU13,"E")*8)+($AV$9*8))+IF($AQ$9=1,IF(OR(AQ13="sl",AQ13="v",AQ13="ml",AQ13="e",AQ13="t",AQ13="cl",AQ13="cal"),-8,0))+IF($AR$9=1,IF(OR(AR13="sl",AR13="v",AR13="ml",AR13="e",AR13="t",AR13="cl",AR13="cal"),-8,0))+IF($AS$9=1,IF(OR(AS13="sl",AS13="v",AS13="ml",AS13="e",AS13="t",AS13="cl",AS13="cal"),-8,0))+IF($AT$9=1,IF(OR(AT13="sl",AT13="v",AT13="ml",AT13="e",AT13="t",AT13="cl",AT13="cal"),-8,0))+IF($AU$9=1,IF(OR(AU13="sl",AU13="v",AU13="ml",AU13="e",AU13="t",AU13="cl",AU13="cal"),-8,0)) -> 18 | BH13: =IF(AND(BK13<0,BJ13>0),0,(IF(AND(BL13<0,BY13>1),0,IF(AND(BA13="",BB13="",BC13="",BD13="",BE13="",BF13="",BG13=""),0,IF(AND(BA13="",BB13="",BC13="",BD13="",BE13="",BF13="",BG13=""),0,SUM(BA13:BG13)-40-BI13)+(COUNTIF(BC13:BG13,"v")*8)+(COUNTIF(BC13:BG13,"sl")*8)+(COUNTIF(BC13:BG13,"ml")*8)+(COUNTIF(BC13:BG13,"t")*8)+(COUNTIF(BC13:BG13,"cl")*8)+(COUNTIF(BC13:BG13,"el")*8)+(COUNTIF(BC13:BG13,"cal")*8)+(COUNTIF(BC13:BG13,"E")*8)+($BH$9*8))+IF($BC$9=1,IF(OR(BC13="sl",BC13="v",BC13="ml",BC13="e",BC13="t",BC13="cl",BC13="cal"),-8,0))+IF($BD$9=1,IF(OR(BD13="sl",BD13="v",BD13="ml",BD13="e",BD13="t",BD13="cl",BD13="cal"),-8,0))+IF($BE$9=1,IF(OR(BE13="sl",BE13="v",BE13="ml",BE13="e",BE13="t",BE13="cl",BE13="cal"),-8,0))+IF($BF$9=1,IF(OR(BF13="sl",BF13="v",BF13="ml",BF13="e",BF13="t",BF13="cl",BF13="cal"),-8,0))+IF($BG$9=1,IF(OR(BG13="sl",BG13="v",BG13="ml",BG13="e",BG13="t",BG13="cl",BG13="cal"),-8,0))))) -> 0 | BI13: =SUMIF(BA$9:BG$9,1,BA13:BG13) -> 0 | BJ13: =COUNTIF(BA13:BB13,14)+IF(AND($BC$9=0,BC13=14),1,0)+IF(AND($BD$9=0,BD13=14),1,0)+IF(AND($BE$9=0,BE13=14),1,0)+IF(AND($BF$9=0,BF13=14),1,0)+IF(AND($BG$9=0,BG13=14),1,0) -> 0 | BK13: =IF(AND(BL13<0,BY13>1),0,IF(AND(BA13="",BB13="",BC13="",BD13="",BE13="",BF13="",BG13=""),0,IF(AND(BA13="",BB13="",BC13="",BD13="",BE13="",BF13="",BG13=""),0,SUM(BA13:BG13)-40-BI13)+(COUNTIF(BC13:BG13,"v")*8)+(COUNTIF(BC13:BG13,"sl")*8)+(COUNTIF(BC13:BG13,"ml")*8)+(COUNTIF(BC13:BG13,"t")*8)+(COUNTIF(BC13:BG13,"cl")*8)+(COUNTIF(BC13:BG13,"el")*8)+(COUNTIF(BC13:BG13,"cal")*8)+(COUNTIF(BC13:BG13,"E")*8)+($BH$9*8))+IF($BC$9=1,IF(OR(BC13="sl",BC13="v",BC13="ml",BC13="e",BC13="t",BC13="cl",BC13="cal"),-8,0))+IF($BD$9=1,IF(OR(BD13="sl",BD13="v",BD13="ml",BD13="e",BD13="t",BD13="cl",BD13="cal"),-8,0))+IF($BE$9=1,IF(OR(BE13="sl",BE13="v",BE13="ml",BE13="e",BE13="t",BE13="cl",BE13="cal"),-8,0))+IF($BF$9=1,IF(OR(BF13="sl",BF13="v",BF13="ml",BF13="e",BF13="t",BF13="cl",BF13="cal"),-8,0))+IF($BG$9=1,IF(OR(BG13="sl",BG13="v",BG13="ml",BG13="e",BG13="t",BG13="cl",BG13="cal"),-8,0))) -> 0 | BL13: =IF(AND(BA13="",BB13="",BC13="",BD13="",BE13="",BF13="",BG13=""),0,IF(AND(BA13="",BB13="",BC13="",BD13="",BE13="",BF13="",BG13=""),0,SUM(BA13:BG13)-40-BI13)+(COUNTIF(BC13:BG13,"v")*8)+(COUNTIF(BC13:BG13,"sl")*8)+(COUNTIF(BC13:BG13,"ml")*8)+(COUNTIF(BC13:BG13,"t")*8)+(COUNTIF(BC13:BG13,"cl")*8)+(COUNTIF(BC13:BG13,"el")*8)+(COUNTIF(BC13:BG13,"cal")*8)+(COUNTIF(BC13:BG13,"E")*8)+($BH$9*8))+IF($BC$9=1,IF(OR(BC13="sl",BC13="v",BC13="ml",BC13="e",BC13="t",BC13="cl",BC13="cal"),-8,0))+IF($BD$9=1,IF(OR(BD13="sl",BD13="v",BD13="ml",BD13="e",BD13="t",BD13="cl",BD13="cal"),-8,0))+IF($BE$9=1,IF(OR(BE13="sl",BE13="v",BE13="ml",BE13="e",BE13="t",BE13="cl",BE13="cal"),-8,0))+IF($BF$9=1,IF(OR(BF13="sl",BF13="v",BF13="ml",BF13="e",BF13="t",BF13="cl",BF13="cal"),-8,0))+IF($BG$9=1,IF(OR(BG13="sl",BG13="v",BG13="ml",BG13="e",BG13="t",BG13="cl",BG13="cal"),-8,0)) -> 0 | BT13: =IF(AND(BW13<0,BV13>0),0,(IF(AND(BX13<0,BY13>1),0,IF(AND(BM13="",BN13="",BO13="",BP13="",BQ13="",BR13="",BS13=""),0,IF(AND(BM13="",BN13="",BO13="",BP13="",BQ13="",BR13="",BS13=""),0,SUM(BM13:BS13)-40-BU13)+(COUNTIF(BO13:BS13,"v")*8)+(COUNTIF(BO13:BS13,"sl")*8)+(COUNTIF(BO13:BS13,"ml")*8)+(COUNTIF(BO13:BS13,"t")*8)+(COUNTIF(BO13:BS13,"cl")*8)+(COUNTIF(BO13:BS13,"el")*8)+(COUNTIF(BO13:BS13,"cal")*8)+(COUNTIF(BO13:BS13,"E")*8)+($BT$9*8))+IF($BO$9=1,IF(OR(BO13="sl",BO13="v",BO13="ml",BO13="e",BO13="t",BO13="cl",BO13="cal"),-8,0))+IF($BP$9=1,IF(OR(BP13="sl",BP13="v",BP13="ml",BP13="e",BP13="t",BP13="cl",BP13="cal"),-8,0))+IF($BQ$9=1,IF(OR(BQ13="sl",BQ13="v",BQ13="ml",BQ13="e",BQ13="t",BQ13="cl",BQ13="cal"),-8,0))+IF($BR$9=1,IF(OR(BR13="sl",BR13="v",BR13="ml",BR13="e",BR13="t",BR13="cl",BR13="cal"),-8,0))+IF($BS$9=1,IF(OR(BS13="sl",BS13="v",BS13="ml",BS13="e",BS13="t",BS13="cl",BS13="cal"),-8,0))))) -> 0 | BU13: =SUMIF(BM$9:BS$9,1,BM13:BS13) -> 0 | BV13: =COUNTIF(BM13:BN13,14)+IF(AND($BO$9=0,BO13=14),1,0)+IF(AND($BP$9=0,BP13=14),1,0)+IF(AND($BQ$9=0,BQ13=14),1,0)+IF(AND($BR$9=0,BR13=14),1,0)+IF(AND($BS$9=0,BS13=14),1,0) -> 0 | BW13: =IF(AND(BX13<0,BY13>1),0,IF(AND(BM13="",BN13="",BO13="",BP13="",BQ13="",BR13="",BS13=""),0,IF(AND(BM13="",BN13="",BO13="",BP13="",BQ13="",BR13="",BS13=""),0,SUM(BM13:BS13)-40-BU13)+(COUNTIF(BO13:BS13,"v")*8)+(COUNTIF(BO13:BS13,"sl")*8)+(COUNTIF(BO13:BS13,"ml")*8)+(COUNTIF(BO13:BS13,"t")*8)+(COUNTIF(BO13:BS13,"cl")*8)+(COUNTIF(BO13:BS13,"el")*8)+(COUNTIF(BO13:BS13,"cal")*8)+(COUNTIF(BO13:BS13,"E")*8)+($BT$9*8))+IF($BO$9=1,IF(OR(BO13="sl",BO13="v",BO13="ml",BO13="e",BO13="t",BO13="cl",BO13="cal"),-8,0))+IF($BP$9=1,IF(OR(BP13="sl",BP13="v",BP13="ml",BP13="e",BP13="t",BP13="cl",BP13="cal"),-8,0))+IF($BQ$9=1,IF(OR(BQ13="sl",BQ13="v",BQ13="ml",BQ13="e",BQ13="t",BQ13="cl",BQ13="cal"),-8,0))+IF($BR$9=1,IF(OR(BR13="sl",BR13="v",BR13="ml",BR13="e",BR13="t",BR13="cl",BR13="cal"),-8,0))+IF($BS$9=1,IF(OR(BS13="sl",BS13="v",BS13="ml",BS13="e",BS13="t",BS13="cl",BS13="cal"),-8,0))) -> 0 | BX13: =IF(AND(BM13="",BN13="",BO13="",BP13="",BQ13="",BR13="",BS13=""),0,IF(AND(BM13="",BN13="",BO13="",BP13="",BQ13="",BR13="",BS13=""),0,SUM(BM13:BS13)-40-BU13)+(COUNTIF(BO13:BS13,"v")*8)+(COUNTIF(BO13:BS13,"sl")*8)+(COUNTIF(BO13:BS13,"ml")*8)+(COUNTIF(BO13:BS13,"t")*8)+(COUNTIF(BO13:BS13,"cl")*8)+(COUNTIF(BO13:BS13,"el")*8)+(COUNTIF(BO13:BS13,"cal")*8)+(COUNTIF(BO13:BS13,"E")*8)+($BT$9*8))+IF($BO$9=1,IF(OR(BO13="sl",BO13="v",BO13="ml",BO13="e",BO13="t",BO13="cl",BO13="cal"),-8,0))+IF($BP$9=1,IF(OR(BP13="sl",BP13="v",BP13="ml",BP13="e",BP13="t",BP13="cl",BP13="cal"),-8,0))+IF($BQ$9=1,IF(OR(BQ13="sl",BQ13="v",BQ13="ml",BQ13="e",BQ13="t",BQ13="cl",BQ13="cal"),-8,0))+IF($BR$9=1,IF(OR(BR13="sl",BR13="v",BR13="ml",BR13="e",BR13="t",BR13="cl",BR13="cal"),-8,0))+IF($BS$9=1,IF(OR(BS13="sl",BS13="v",BS13="ml",BS13="e",BS13="t",BS13="cl",BS13="cal"),-8,0)) -> 0 | BY13: =SUM(N13,Z13,AL13,AX13,BJ13,BV13) -> 5 | BZ13: =IF(SUM(AV13,BH13,AJ13,X13,L13,BT13)<0,0,SUM(AV13,BH13,AJ13,X13,L13,BT13)) -> 39 | CA13: =SUM(AW13,BI13,AK13,Y13,M13,BU13) -> 0 | CB13: =(BZ13*CC13)+(CA13*CD13) -> 54290.84 | CC13: =D13*12/2080*1.5 -> 1392.0728 | CD13: =D13*12/2080*2 -> 1856.0971
